2019-10-24 04:39:02,916 - selenium - INFO - 在section：environment下读取browser的值
2019-10-24 04:39:02,916 - selenium - INFO - Read browser configuration, value：chrome
2019-10-24 04:39:02,916 - selenium - INFO - 在section：environment下读取url的值
2019-10-24 04:39:02,916 - selenium - INFO - Read url configuration, value：http://blr.9161252.com
2019-10-24 04:39:04,850 - selenium - ERROR - Browser open error
Traceback (most recent call last):
  File "/root/PycharmProjects/blr.9161252.com/Common/basePage.py", line 114, in open_browser
    self.driver = webdriver.Chrome()
  File "/root/PycharmProjects/blr.9161252.com/venv/lib/python3.7/site-packages/selenium/webdriver/chrome/webdriver.py", line 81, in __init__
    desired_capabilities=desired_capabilities)
  File "/root/PycharmProjects/blr.9161252.com/venv/lib/python3.7/site-packages/selenium/webdriver/remote/webdriver.py", line 157, in __init__
    self.start_session(capabilities, browser_profile)
  File "/root/PycharmProjects/blr.9161252.com/venv/lib/python3.7/site-packages/selenium/webdriver/remote/webdriver.py", line 252, in start_session
    response = self.execute(Command.NEW_SESSION, parameters)
  File "/root/PycharmProjects/blr.9161252.com/venv/lib/python3.7/site-packages/selenium/webdriver/remote/webdriver.py", line 321, in execute
    self.error_handler.check_response(response)
  File "/root/PycharmProjects/blr.9161252.com/venv/lib/python3.7/site-packages/selenium/webdriver/remote/errorhandler.py", line 242, in check_response
    raise exception_class(message, screen, stacktrace)
selenium.common.exceptions.WebDriverException: Message: unknown error: Chrome failed to start: exited abnormally
  (unknown error: DevToolsActivePort file doesn't exist)
  (The process started from chrome location /usr/bin/chromium is no longer running, so ChromeDriver is assuming that Chrome has crashed.)

